Workbook

Sheet DASHBOARD
A1: MANAGEMENT DASHBOARD
A2: Live KPIs — updates automatically as you enter data. All values GBP (£). Reporting date is set on the SETTINGS sheet.
B4: STOCK | E4: SALES | H4: PROFIT & TRADING | K4: ⚠ WARNINGS / EXCEPTIONS
B5: Total stock items | C5: =COUNTA('INVENTORY MASTER'!$A$4:$A$63) -> 6 | E5: Today's sales | F5: =SUMIFS(SALES!$K$4:$K$63,SALES!$B$4:$B$63,SETTINGS!$W$6) -> 0 | H5: Gross profit this month | I5: =SUMIFS(SALES!$N$4:$N$63,SALES!$B$4:$B$63,">="&SETTINGS!$W$7,SALES!$B$4:$B$63,"<="&SETTINGS!$W$8) -> 0 | K5: Stock below minimum price | L5: =SUMPRODUCT(('INVENTORY MASTER'!$AO$4:$AO$63<>"")*('INVENTORY MASTER'!$AN$4:$AN$63<>"")*('INVENTORY MASTER'!$AO$4:$AO$63<'INVENTORY MASTER'!$AN$4:$AN$63)) -> 0
B6: Watches | C6: =COUNTIF('INVENTORY MASTER'!$E$4:$E$63,"Watch") -> 3 | E6: This week's sales | F6: =SUMIFS(SALES!$K$4:$K$63,SALES!$B$4:$B$63,">="&SETTINGS!$W$11,SALES!$B$4:$B$63,"<="&SETTINGS!$W$6) -> 0 | H6: Gross profit this year | I6: =SUMIFS(SALES!$N$4:$N$63,SALES!$B$4:$B$63,">="&SETTINGS!$W$9,SALES!$B$4:$B$63,"<="&SETTINGS!$W$10) -> 2100 | K6: Missing / lost stock | L6: =COUNTIF('INVENTORY MASTER'!$AS$4:$AS$63,"Lost/Missing") -> 0
B7: Jewellery items | C7: =COUNTIF('INVENTORY MASTER'!$E$4:$E$63,"Ring")+COUNTIF('INVENTORY MASTER'!$E$4:$E$63,"Bracelet")+COUNTIF('INVENTORY MASTER'!$E$4:$E$63,"Necklace")+COUNTIF('INVENTORY MASTER'!$E$4:$E$63,"Pendant")+COUNTIF('INVENTORY MASTER'!$E$4:$E$63,"Earrings")+COUNTIF('INVENTORY MASTER'!$E$4:$E$63,"Chain")+COUNTIF('INVENTORY MASTER'!$E$4:$E$63,"Gold")+COUNTIF('INVENTORY MASTER'!$E$4:$E$63,"Diamond Jewellery") -> 3 | E7: Sales this month | F7: =SUMIFS(SALES!$K$4:$K$63,SALES!$B$4:$B$63,">="&SETTINGS!$W$7,SALES!$B$4:$B$63,"<="&SETTINGS!$W$8) -> 0 | H7: Avg gross profit / sale | I7: =IFERROR(SUMIFS(SALES!$N$4:$N$63,SALES!$B$4:$B$63,">="&SETTINGS!$W$9,SALES!$B$4:$B$63,"<="&SETTINGS!$W$10)/COUNTIFS(SALES!$B$4:$B$63,">="&SETTINGS!$W$9,SALES!$B$4:$B$63,"<="&SETTINGS!$W$10),0) -> 2100 | K7: Overdue stock movements | L7: =SUMPRODUCT(('STOCK MOVEMENT'!$K$4:$K$63<>"")*('STOCK MOVEMENT'!$K$4:$K$63<SETTINGS!$W$6)*('STOCK MOVEMENT'!$M$4:$M$63<>"Yes")*('STOCK MOVEMENT'!$L$4:$L$63="")) -> 1
B8: Available items | C8: =COUNTIF('INVENTORY MASTER'!$AS$4:$AS$63,"Available") -> 4 | E8: Sales this year | F8: =SUMIFS(SALES!$K$4:$K$63,SALES!$B$4:$B$63,">="&SETTINGS!$W$9,SALES!$B$4:$B$63,"<="&SETTINGS!$W$10) -> 10200 | H8: Avg gross margin % | I8: =IFERROR(SUMIFS(SALES!$N$4:$N$63,SALES!$B$4:$B$63,">="&SETTINGS!$W$9,SALES!$B$4:$B$63,"<="&SETTINGS!$W$10)/SUMIFS(SALES!$K$4:$K$63,SALES!$B$4:$B$63,">="&SETTINGS!$W$9,SALES!$B$4:$B$63,"<="&SETTINGS!$W$10),0) -> 0.20588235 | K8: Negative-margin sales | L8: =COUNTIF(SALES!$N$4:$N$63,"<0") -> 0
B9: Reserved items | C9: =COUNTIF('INVENTORY MASTER'!$AS$4:$AS$63,"Reserved") -> 0 | E9: Number of sales (year) | F9: =COUNTIFS(SALES!$B$4:$B$63,">="&SETTINGS!$W$9,SALES!$B$4:$B$63,"<="&SETTINGS!$W$10) -> 1 | H9: Operating expenses this month | I9: =SUMIFS(EXPENSES!$I$4:$I$83,EXPENSES!$B$4:$B$83,">="&SETTINGS!$W$7,EXPENSES!$B$4:$B$83,"<="&SETTINGS!$W$8) -> 0 | K9: Missing serial (watches) | L9: =SUMPRODUCT(('INVENTORY MASTER'!$A$4:$A$63<>"")*('INVENTORY MASTER'!$E$4:$E$63="Watch")*('INVENTORY MASTER'!$J$4:$J$63="")) -> 0
B10: Sold items | C10: =COUNTIF('INVENTORY MASTER'!$AS$4:$AS$63,"Sold") -> 1 | H10: Operating expenses this year | I10: =SUMIFS(EXPENSES!$I$4:$I$83,EXPENSES!$B$4:$B$83,">="&SETTINGS!$W$9,EXPENSES!$B$4:$B$83,"<="&SETTINGS!$W$10) -> 8720 | K10: Duplicate serial numbers | L10: =SUMPRODUCT(('INVENTORY MASTER'!$J$4:$J$63<>"")*(COUNTIF('INVENTORY MASTER'!$J$4:$J$63,'INVENTORY MASTER'!$J$4:$J$63&"")>1)) -> 0
B11: Items outside premises | C11: =SUMPRODUCT(('INVENTORY MASTER'!$A$4:$A$63<>"")*('INVENTORY MASTER'!$AS$4:$AS$63<>"Sold")*('INVENTORY MASTER'!$AR$4:$AR$63<>"Shop Display")*('INVENTORY MASTER'!$AR$4:$AR$63<>"Shop Safe")*('INVENTORY MASTER'!$AR$4:$AR$63<>"Office")) -> 1 | E11: PARTNERS | H11: Net trading result (year) | I11: =I6-I10 -> -6620 | K11: Missing purchase price | L11: =SUMPRODUCT(('INVENTORY MASTER'!$A$4:$A$63<>"")*('INVENTORY MASTER'!$AE$4:$AE$63="")) -> 0
B12: Missing items | C12: =COUNTIF('INVENTORY MASTER'!$AS$4:$AS$63,"Lost/Missing") -> 0 | E12: Partner 1 outstanding | F12: ='PARTNER SUMMARY'!$B$16 -> 18100 | H12: Potential GP on inventory | I12: =C15 -> 6410 | K12: Missing supplier details | L12: =SUMPRODUCT(('INVENTORY MASTER'!$A$4:$A$63<>"")*('INVENTORY MASTER'!$AA$4:$AA$63="")) -> 0
B13: Total stock at cost | C13: =SUMIF('INVENTORY MASTER'!$AS$4:$AS$63,"<>Sold",'INVENTORY MASTER'!$AI$4:$AI$63)-SUMIF('INVENTORY MASTER'!$AS$4:$AS$63,"Written Off",'INVENTORY MASTER'!$AI$4:$AI$63) -> 14690 | E13: Partner 2 outstanding | F13: ='PARTNER SUMMARY'!$C$16 -> 3550 | H13: Stock below min price (count) | I13: =SUMPRODUCT(('INVENTORY MASTER'!$AO$4:$AO$63<>"")*('INVENTORY MASTER'!$AN$4:$AN$63<>"")*('INVENTORY MASTER'!$AO$4:$AO$63<'INVENTORY MASTER'!$AN$4:$AN$63)) -> 0 | K13: Items without photos/docs | L13: =SUMPRODUCT(('INVENTORY MASTER'!$A$4:$A$63<>"")*('INVENTORY MASTER'!$AS$4:$AS$63<>"Sold")*('INVENTORY MASTER'!$BA$4:$BA$63="")) -> 1
B14: Expected retail value | C14: =SUMIF('INVENTORY MASTER'!$AS$4:$AS$63,"<>Sold",'INVENTORY MASTER'!$AM$4:$AM$63)-SUMIF('INVENTORY MASTER'!$AS$4:$AS$63,"Written Off",'INVENTORY MASTER'!$AM$4:$AM$63) -> 21100 | E14: Partner 3 outstanding | F14: ='PARTNER SUMMARY'!$D$16 -> 7790 | H14: Discounts > 20%% (count) | I14: =COUNTIF(SALES!$M$4:$M$63,">0.2") -> 0 | K14: Sold but still 'Available' | L14: =SUMPRODUCT(('INVENTORY MASTER'!$AT$4:$AT$63<>"")*('INVENTORY MASTER'!$AS$4:$AS$63="Available")) -> 0
B15: Potential stock profit | C15: =C14-C13 -> 6410 | E15: Total partner funding outstanding | F15: ='PARTNER SUMMARY'!$E$16 -> 29440 | H15: Negative-margin sales (count) | I15: =COUNTIF(SALES!$N$4:$N$63,"<0") -> 0 | K15: Unreconciled partner txns | L15: =COUNTIF('PARTNER CONTRIBUTIONS'!$M$4:$M$63,">0") -> 5
B19: MONTHLY PERFORMANCE (reporting year) | F19: BY CATEGORY | J19: BY EMPLOYEE | M19: EXPENSES BY CATEGORY
B20: Month | C20: Sales | D20: Gross Profit | F20: Category | G20: Sales | H20: Stock Value | J20: Employee | K20: Sales | M20: Category | N20: Amount
B21: Jan | C21: =SUMIFS(SALES!$K$4:$K$63,SALES!$B$4:$B$63,">="&DATE(YEAR(SETTINGS!$W$9),1,1),SALES!$B$4:$B$63,"<="&EOMONTH(DATE(YEAR(SETTINGS!$W$9),1,1),0)) -> 0 | D21: =SUMIFS(SALES!$N$4:$N$63,SALES!$B$4:$B$63,">="&DATE(YEAR(SETTINGS!$W$9),1,1),SALES!$B$4:$B$63,"<="&EOMONTH(DATE(YEAR(SETTINGS!$W$9),1,1),0)) -> 0 | F21: Watch | G21: =SUMIFS(SALES!$K$4:$K$63,SALES!$E$4:$E$63,"Watch") -> 10200 | H21: =SUMIFS('INVENTORY MASTER'!$AI$4:$AI$63,'INVENTORY MASTER'!$E$4:$E$63,"Watch")-SUMIFS('INVENTORY MASTER'!$AI$4:$AI$63,'INVENTORY MASTER'!$E$4:$E$63,"Watch",'INVENTORY MASTER'!$AS$4:$AS$63,"Sold")-SUMIFS('INVENTORY MASTER'!$AI$4:$AI$63,'INVENTORY MASTER'!$E$4:$E$63,"Watch",'INVENTORY MASTER'!$AS$4:$AS$63,"Written Off") -> 7990 | J21: Sarah Hughes | K21: =SUMIFS(SALES!$K$4:$K$63,SALES!$F$4:$F$63,"Sarah Hughes") -> 10200 | M21: Rent | N21: =SUMIFS(EXPENSES!$I$4:$I$83,EXPENSES!$D$4:$D$83,"Rent") -> 3000
B22: Feb | C22: =SUMIFS(SALES!$K$4:$K$63,SALES!$B$4:$B$63,">="&DATE(YEAR(SETTINGS!$W$9),2,1),SALES!$B$4:$B$63,"<="&EOMONTH(DATE(YEAR(SETTINGS!$W$9),2,1),0)) -> 10200 | D22: =SUMIFS(SALES!$N$4:$N$63,SALES!$B$4:$B$63,">="&DATE(YEAR(SETTINGS!$W$9),2,1),SALES!$B$4:$B$63,"<="&EOMONTH(DATE(YEAR(SETTINGS!$W$9),2,1),0)) -> 2100 | F22: Ring | G22: =SUMIFS(SALES!$K$4:$K$63,SALES!$E$4:$E$63,"Ring") -> 0 | H22: =SUMIFS('INVENTORY MASTER'!$AI$4:$AI$63,'INVENTORY MASTER'!$E$4:$E$63,"Ring")-SUMIFS('INVENTORY MASTER'!$AI$4:$AI$63,'INVENTORY MASTER'!$E$4:$E$63,"Ring",'INVENTORY MASTER'!$AS$4:$AS$63,"Sold")-SUMIFS('INVENTORY MASTER'!$AI$4:$AI$63,'INVENTORY MASTER'!$E$4:$E$63,"Ring",'INVENTORY MASTER'!$AS$4:$AS$63,"Written Off") -> 0 | J22: James Patel | K22: =SUMIFS(SALES!$K$4:$K$63,SALES!$F$4:$F$63,"James Patel") -> 0 | M22: Refurbishment | N22: =SUMIFS(EXPENSES!$I$4:$I$83,EXPENSES!$D$4:$D$83,"Refurbishment") -> 5000
B23: Mar | C23: =SUMIFS(SALES!$K$4:$K$63,SALES!$B$4:$B$63,">="&DATE(YEAR(SETTINGS!$W$9),3,1),SALES!$B$4:$B$63,"<="&EOMONTH(DATE(YEAR(SETTINGS!$W$9),3,1),0)) -> 0 | D23: =SUMIFS(SALES!$N$4:$N$63,SALES!$B$4:$B$63,">="&DATE(YEAR(SETTINGS!$W$9),3,1),SALES!$B$4:$B$63,"<="&EOMONTH(DATE(YEAR(SETTINGS!$W$9),3,1),0)) -> 0 | F23: Bracelet | G23: =SUMIFS(SALES!$K$4:$K$63,SALES!$E$4:$E$63,"Bracelet") -> 0 | H23: =SUMIFS('INVENTORY MASTER'!$AI$4:$AI$63,'INVENTORY MASTER'!$E$4:$E$63,"Bracelet")-SUMIFS('INVENTORY MASTER'!$AI$4:$AI$63,'INVENTORY MASTER'!$E$4:$E$63,"Bracelet",'INVENTORY MASTER'!$AS$4:$AS$63,"Sold")-SUMIFS('INVENTORY MASTER'!$AI$4:$AI$63,'INVENTORY MASTER'!$E$4:$E$63,"Bracelet",'INVENTORY MASTER'!$AS$4:$AS$63,"Written Off") -> 1650 | J23: Olivia Brown | K23: =SUMIFS(SALES!$K$4:$K$63,SALES!$F$4:$F$63,"Olivia Brown") -> 0 | M23: Insurance | N23: =SUMIFS(EXPENSES!$I$4:$I$83,EXPENSES!$D$4:$D$83,"Insurance") -> 0
B24: Apr | C24: =SUMIFS(SALES!$K$4:$K$63,SALES!$B$4:$B$63,">="&DATE(YEAR(SETTINGS!$W$9),4,1),SALES!$B$4:$B$63,"<="&EOMONTH(DATE(YEAR(SETTINGS!$W$9),4,1),0)) -> 0 | D24: =SUMIFS(SALES!$N$4:$N$63,SALES!$B$4:$B$63,">="&DATE(YEAR(SETTINGS!$W$9),4,1),SALES!$B$4:$B$63,"<="&EOMONTH(DATE(YEAR(SETTINGS!$W$9),4,1),0)) -> 0 | F24: Necklace | G24: =SUMIFS(SALES!$K$4:$K$63,SALES!$E$4:$E$63,"Necklace") -> 0 | H24: =SUMIFS('INVENTORY MASTER'!$AI$4:$AI$63,'INVENTORY MASTER'!$E$4:$E$63,"Necklace")-SUMIFS('INVENTORY MASTER'!$AI$4:$AI$63,'INVENTORY MASTER'!$E$4:$E$63,"Necklace",'INVENTORY MASTER'!$AS$4:$AS$63,"Sold")-SUMIFS('INVENTORY MASTER'!$AI$4:$AI$63,'INVENTORY MASTER'!$E$4:$E$63,"Necklace",'INVENTORY MASTER'!$AS$4:$AS$63,"Written Off") -> 0 | J24: David Khan | K24: =SUMIFS(SALES!$K$4:$K$63,SALES!$F$4:$F$63,"David Khan") -> 0 | M24: Staff Wages | N24: =SUMIFS(EXPENSES!$I$4:$I$83,EXPENSES!$D$4:$D$83,"Staff Wages") -> 0
B25: May | C25: =SUMIFS(SALES!$K$4:$K$63,SALES!$B$4:$B$63,">="&DATE(YEAR(SETTINGS!$W$9),5,1),SALES!$B$4:$B$63,"<="&EOMONTH(DATE(YEAR(SETTINGS!$W$9),5,1),0)) -> 0 | D25: =SUMIFS(SALES!$N$4:$N$63,SALES!$B$4:$B$63,">="&DATE(YEAR(SETTINGS!$W$9),5,1),SALES!$B$4:$B$63,"<="&EOMONTH(DATE(YEAR(SETTINGS!$W$9),5,1),0)) -> 0 | F25: Pendant | G25: =SUMIFS(SALES!$K$4:$K$63,SALES!$E$4:$E$63,"Pendant") -> 0 | H25: =SUMIFS('INVENTORY MASTER'!$AI$4:$AI$63,'INVENTORY MASTER'!$E$4:$E$63,"Pendant")-SUMIFS('INVENTORY MASTER'!$AI$4:$AI$63,'INVENTORY MASTER'!$E$4:$E$63,"Pendant",'INVENTORY MASTER'!$AS$4:$AS$63,"Sold")-SUMIFS('INVENTORY MASTER'!$AI$4:$AI$63,'INVENTORY MASTER'!$E$4:$E$63,"Pendant",'INVENTORY MASTER'!$AS$4:$AS$63,"Written Off") -> 0 | M25: Marketing | N25: =SUMIFS(EXPENSES!$I$4:$I$83,EXPENSES!$D$4:$D$83,"Marketing") -> 0
B26: Jun | C26: =SUMIFS(SALES!$K$4:$K$63,SALES!$B$4:$B$63,">="&DATE(YEAR(SETTINGS!$W$9),6,1),SALES!$B$4:$B$63,"<="&EOMONTH(DATE(YEAR(SETTINGS!$W$9),6,1),0)) -> 0 | D26: =SUMIFS(SALES!$N$4:$N$63,SALES!$B$4:$B$63,">="&DATE(YEAR(SETTINGS!$W$9),6,1),SALES!$B$4:$B$63,"<="&EOMONTH(DATE(YEAR(SETTINGS!$W$9),6,1),0)) -> 0 | F26: Earrings | G26: =SUMIFS(SALES!$K$4:$K$63,SALES!$E$4:$E$63,"Earrings") -> 0 | H26: =SUMIFS('INVENTORY MASTER'!$AI$4:$AI$63,'INVENTORY MASTER'!$E$4:$E$63,"Earrings")-SUMIFS('INVENTORY MASTER'!$AI$4:$AI$63,'INVENTORY MASTER'!$E$4:$E$63,"Earrings",'INVENTORY MASTER'!$AS$4:$AS$63,"Sold")-SUMIFS('INVENTORY MASTER'!$AI$4:$AI$63,'INVENTORY MASTER'!$E$4:$E$63,"Earrings",'INVENTORY MASTER'!$AS$4:$AS$63,"Written Off") -> 0 | M26: Stock Insurance | N26: =SUMIFS(EXPENSES!$I$4:$I$83,EXPENSES!$D$4:$D$83,"Stock Insurance") -> 720
B27: Jul | C27: =SUMIFS(SALES!$K$4:$K$63,SALES!$B$4:$B$63,">="&DATE(YEAR(SETTINGS!$W$9),7,1),SALES!$B$4:$B$63,"<="&EOMONTH(DATE(YEAR(SETTINGS!$W$9),7,1),0)) -> 0 | D27: =SUMIFS(SALES!$N$4:$N$63,SALES!$B$4:$B$63,">="&DATE(YEAR(SETTINGS!$W$9),7,1),SALES!$B$4:$B$63,"<="&EOMONTH(DATE(YEAR(SETTINGS!$W$9),7,1),0)) -> 0 | F27: Chain | G27: =SUMIFS(SALES!$K$4:$K$63,SALES!$E$4:$E$63,"Chain") -> 0 | H27: =SUMIFS('INVENTORY MASTER'!$AI$4:$AI$63,'INVENTORY MASTER'!$E$4:$E$63,"Chain")-SUMIFS('INVENTORY MASTER'!$AI$4:$AI$63,'INVENTORY MASTER'!$E$4:$E$63,"Chain",'INVENTORY MASTER'!$AS$4:$AS$63,"Sold")-SUMIFS('INVENTORY MASTER'!$AI$4:$AI$63,'INVENTORY MASTER'!$E$4:$E$63,"Chain",'INVENTORY MASTER'!$AS$4:$AS$63,"Written Off") -> 0 | M27: Business Rates | N27: =SUMIFS(EXPENSES!$I$4:$I$83,EXPENSES!$D$4:$D$83,"Business Rates") -> 0
B28: Aug | C28: =SUMIFS(SALES!$K$4:$K$63,SALES!$B$4:$B$63,">="&DATE(YEAR(SETTINGS!$W$9),8,1),SALES!$B$4:$B$63,"<="&EOMONTH(DATE(YEAR(SETTINGS!$W$9),8,1),0)) -> 0 | D28: =SUMIFS(SALES!$N$4:$N$63,SALES!$B$4:$B$63,">="&DATE(YEAR(SETTINGS!$W$9),8,1),SALES!$B$4:$B$63,"<="&EOMONTH(DATE(YEAR(SETTINGS!$W$9),8,1),0)) -> 0 | F28: Gold | G28: =SUMIFS(SALES!$K$4:$K$63,SALES!$E$4:$E$63,"Gold") -> 0 | H28: =SUMIFS('INVENTORY MASTER'!$AI$4:$AI$63,'INVENTORY MASTER'!$E$4:$E$63,"Gold")-SUMIFS('INVENTORY MASTER'!$AI$4:$AI$63,'INVENTORY MASTER'!$E$4:$E$63,"Gold",'INVENTORY MASTER'!$AS$4:$AS$63,"Sold")-SUMIFS('INVENTORY MASTER'!$AI$4:$AI$63,'INVENTORY MASTER'!$E$4:$E$63,"Gold",'INVENTORY MASTER'!$AS$4:$AS$63,"Written Off") -> 1500 | M28: Software | N28: =SUMIFS(EXPENSES!$I$4:$I$83,EXPENSES!$D$4:$D$83,"Software") -> 0
B29: Sep | C29: =SUMIFS(SALES!$K$4:$K$63,SALES!$B$4:$B$63,">="&DATE(YEAR(SETTINGS!$W$9),9,1),SALES!$B$4:$B$63,"<="&EOMONTH(DATE(YEAR(SETTINGS!$W$9),9,1),0)) -> 0 | D29: =SUMIFS(SALES!$N$4:$N$63,SALES!$B$4:$B$63,">="&DATE(YEAR(SETTINGS!$W$9),9,1),SALES!$B$4:$B$63,"<="&EOMONTH(DATE(YEAR(SETTINGS!$W$9),9,1),0)) -> 0 | F29: Diamond Jewellery | G29: =SUMIFS(SALES!$K$4:$K$63,SALES!$E$4:$E$63,"Diamond Jewellery") -> 0 | H29: =SUMIFS('INVENTORY MASTER'!$AI$4:$AI$63,'INVENTORY MASTER'!$E$4:$E$63,"Diamond Jewellery")-SUMIFS('INVENTORY MASTER'!$AI$4:$AI$63,'INVENTORY MASTER'!$E$4:$E$63,"Diamond Jewellery",'INVENTORY MASTER'!$AS$4:$AS$63,"Sold")-SUMIFS('INVENTORY MASTER'!$AI$4:$AI$63,'INVENTORY MASTER'!$E$4:$E$63,"Diamond Jewellery",'INVENTORY MASTER'!$AS$4:$AS$63,"Written Off") -> 3550 | M29: Miscellaneous | N29: =SUMIFS(EXPENSES!$I$4:$I$83,EXPENSES!$D$4:$D$83,"Miscellaneous") -> 0
B30: Oct | C30: =SUMIFS(SALES!$K$4:$K$63,SALES!$B$4:$B$63,">="&DATE(YEAR(SETTINGS!$W$9),10,1),SALES!$B$4:$B$63,"<="&EOMONTH(DATE(YEAR(SETTINGS!$W$9),10,1),0)) -> 0 | D30: =SUMIFS(SALES!$N$4:$N$63,SALES!$B$4:$B$63,">="&DATE(YEAR(SETTINGS!$W$9),10,1),SALES!$B$4:$B$63,"<="&EOMONTH(DATE(YEAR(SETTINGS!$W$9),10,1),0)) -> 0 | F30: Other | G30: =SUMIFS(SALES!$K$4:$K$63,SALES!$E$4:$E$63,"Other") -> 0 | H30: =SUMIFS('INVENTORY MASTER'!$AI$4:$AI$63,'INVENTORY MASTER'!$E$4:$E$63,"Other")-SUMIFS('INVENTORY MASTER'!$AI$4:$AI$63,'INVENTORY MASTER'!$E$4:$E$63,"Other",'INVENTORY MASTER'!$AS$4:$AS$63,"Sold")-SUMIFS('INVENTORY MASTER'!$AI$4:$AI$63,'INVENTORY MASTER'!$E$4:$E$63,"Other",'INVENTORY MASTER'!$AS$4:$AS$63,"Written Off") -> 0
B31: Nov | C31: =SUMIFS(SALES!$K$4:$K$63,SALES!$B$4:$B$63,">="&DATE(YEAR(SETTINGS!$W$9),11,1),SALES!$B$4:$B$63,"<="&EOMONTH(DATE(YEAR(SETTINGS!$W$9),11,1),0)) -> 0 | D31: =SUMIFS(SALES!$N$4:$N$63,SALES!$B$4:$B$63,">="&DATE(YEAR(SETTINGS!$W$9),11,1),SALES!$B$4:$B$63,"<="&EOMONTH(DATE(YEAR(SETTINGS!$W$9),11,1),0)) -> 0
B32: Dec | C32: =SUMIFS(SALES!$K$4:$K$63,SALES!$B$4:$B$63,">="&DATE(YEAR(SETTINGS!$W$9),12,1),SALES!$B$4:$B$63,"<="&EOMONTH(DATE(YEAR(SETTINGS!$W$9),12,1),0)) -> 0 | D32: =SUMIFS(SALES!$N$4:$N$63,SALES!$B$4:$B$63,">="&DATE(YEAR(SETTINGS!$W$9),12,1),SALES!$B$4:$B$63,"<="&EOMONTH(DATE(YEAR(SETTINGS!$W$9),12,1),0)) -> 0
B34: PARTNER CONTRIBUTIONS vs REIMBURSEMENTS
B35: Partner | C35: Introduced | D35: Reimbursed
B36: Partner 1 | C36: =SUMIFS('PARTNER CONTRIBUTIONS'!$H$4:$H$63,'PARTNER CONTRIBUTIONS'!$C$4:$C$63,"Partner 1") -> 18100 | D36: =SUMIFS('PARTNER CONTRIBUTIONS'!$K$4:$K$63,'PARTNER CONTRIBUTIONS'!$C$4:$C$63,"Partner 1") -> 0
B37: Partner 2 | C37: =SUMIFS('PARTNER CONTRIBUTIONS'!$H$4:$H$63,'PARTNER CONTRIBUTIONS'!$C$4:$C$63,"Partner 2") -> 3550 | D37: =SUMIFS('PARTNER CONTRIBUTIONS'!$K$4:$K$63,'PARTNER CONTRIBUTIONS'!$C$4:$C$63,"Partner 2") -> 0
B38: Partner 3 | C38: =SUMIFS('PARTNER CONTRIBUTIONS'!$H$4:$H$63,'PARTNER CONTRIBUTIONS'!$C$4:$C$63,"Partner 3") -> 9790 | D38: =SUMIFS('PARTNER CONTRIBUTIONS'!$K$4:$K$63,'PARTNER CONTRIBUTIONS'!$C$4:$C$63,"Partner 3") -> 2000

Sheet INSTRUCTIONS
A1: READ ME — How to use this workbook
A2: Jewellery & Luxury Watch Shop Management System · Version 1 · GBP (£) · Dates DD/MM/YYYY
B4: Colour key
B5: Cream cells | C5: You type here (data entry). Example: Purchase Price, Selling Price, dropdowns.
B6: Grey cells | C6: Calculated automatically by formula — do not type over these. They are protected.
B7: Gold band | C7: Section headings / key totals.
B8: Red highlight | C8: A warning that needs attention (below minimum price, missing stock, overdue, negative margin).
B10: Getting started — enter your data in this order
C11: 1. SETTINGS — rename Partner 1/2/3 to real names, set staff names, check ownership % totals 100%.
C12: 2. INVENTORY MASTER — add every item of current stock (use the ID helper on SETTINGS for the next WAT-/JWL- number).
C13: 3. PARTNER CONTRIBUTIONS — record who personally funded each item / cost, and whether it is a loan or capital.
C14: 4. BUILDING & SETUP + EXPENSES — enter refurbishment, rent and other business costs.
C15: 5. SALES — record each sale by Stock ID; cost and profit fill in automatically.
C16: 6. Check the DASHBOARD — all KPIs, charts and warnings update automatically.
B18: Partner accounting principle (important)
B19: Paid By ≠ Ownership | C19: Who paid for an item does NOT mean they own it. Record the funding nature (Partner Loan / Capital / Business Purchase) in 'Funding Type' and log every partner payment in PARTNER CONTRIBUTIONS.
B20: What the business owes | C20: PARTNER CONTRIBUTIONS keeps a running current-account: Amount introduced − Reimbursed = Outstanding. PARTNER SUMMARY and the DASHBOARD show what is owed to each partner.
B21: Profit is NOT auto-split | C21: Ownership % on SETTINGS is informational only. Profit is not divided automatically because ownership may differ from funding.
B23: Profit levels
B24: Item gross profit | C24: Selling Price − Landed Cost (per item). Rent/overheads do NOT affect item gross profit.
B25: Net trading result | C25: Total gross profit − operating expenses. Shown on the DASHBOARD and MONTH-END sheets.
B27: Adding a PHOTO to each item
B28: Best method (Excel 365) | C28: On INVENTORY MASTER, click the 'Photo' cell for the row, then Insert > Pictures > Place in Cell > This Device. The picture sits inside the cell and sorts/filters with the item.
B29: Any Excel version | C29: Save each photo in a folder (or cloud) and put its file path or URL in the 'Photo/Document Link' column.
B30: Sample images | C30: The example rows show floating placeholder pictures so you can see the idea — delete them and use Place in Cell for real stock.
B31: Model vs Serial | C31: 'Model/Ref Number' (e.g. 126610LN) and 'Serial Number' (the unique piece number) are separate columns — fill in both. Watch Details repeats them for watches.
B33: Buying in USD, Dirham (AED) or other currencies
B34: 1. Pick the currency | C34: On INVENTORY MASTER set 'Purchase Currency' (GBP, USD, AED, EUR...) from the dropdown.
B35: 2. Enter the foreign price | C35: Type what you paid in that currency in 'Original Purchase Price' (e.g. 22,000 for AED 22,000).
B36: 3. Rate to GBP | C36: Type the exchange rate you got in 'FX Rate to GBP' (GBP per 1 unit, e.g. USD 0.79). Leave it blank to use the indicative rate on SETTINGS.
B37: Result | C37: 'Purchase Price (GBP)' converts automatically (Original x rate). All profit, stock value and dashboard figures then use the GBP amount — GBP rows always use rate 1.
B38: Update rates | C38: Maintain the CURRENCIES & FX RATES table on SETTINGS. Historical buys keep the exact rate typed on their row, so past costs never change when today's rates move.
B40: Notes & limitations
B41: Example rows | C41: Rows marked 'EXAMPLE' are dummy data — delete them before going live.
B42: Protection / password | C42: Every sheet is READ-ONLY and password protected — staff can view, select, copy and filter, but cannot change anything. A PARTNER edits by: Review ▸ Unprotect Sheet ▸ enter password 643216 ▸ make changes ▸ Review ▸ Protect Sheet (re-enter 643216). The workbook structure is also locked (no adding/removing sheets).
B43: Change the password | C43: Do it per sheet in Excel: Review ▸ Unprotect Sheet (643216), then Review ▸ Protect Sheet and type a new password. Repeat for each sheet, and Review ▸ Protect Workbook for the structure. Keep the password safe — it cannot be recovered if lost.
B44: Open-password (optional) | C44: To also require a password just to OPEN the file, do it in Excel: File ▸ Info ▸ Protect Workbook ▸ Encrypt with Password. (This can only be set in Excel, not generated here.)
B45: Who changed what | C45: Excel cannot auto-log edits without a macro. Record price changes, write-offs and refunds in the AUDIT LOG sheet. Ask if you'd like an automatic macro-based log (.xlsm).
B46: Slicers / PivotTables | C46: Native Excel slicers and PivotTables can be added on top; summary tables here use SUMIFS/COUNTIFS so the file recalculates everywhere, including in the browser.
B47: Migration | C47: Each sheet is a clean table keyed by Stock ID / IDs, ready to export to Airtable, a database or a POS/inventory app.

Sheet INVENTORY MASTER
A1: INVENTORY MASTER
A2: Every physical item entering the business. Cream = you enter · Grey = auto-calculated. 'Paid By' does NOT mean ownership — record ownership in Funding Type & the Partner ledger.
A3: Stock ID | B3: Photo | C3: Barcode/QR Ref | D3: Date Purchased | E3: Category | F3: Subcategory | G3: Brand | H3: Model | I3: Model/Ref Number | J3: Serial Number | K3: Description | L3: Metal | M3: Metal Purity | N3: Weight (g) | O3: Stone Type | P3: Stone Carat | Q3: Diamond Colour | R3: Diamond Clarity | S3: Ring Size | T3: Watch Case Size | U3: Watch Movement | V3: Watch Year | W3: Box Included | X3: Papers Included | Y3: Warranty Included | Z3: Condition | AA3: Supplier Name | AB3: Supplier Type | AC3: Supplier Invoice Ref | AD3: Purchase Currency | AE3: Original Purchase Price | AF3: FX Rate to GBP | AG3: Purchase Price (GBP) | AH3: Additional Costs | AI3: Total Landed Cost | AJ3: Paid By | AK3: Funding Type | AL3: Ownership/Funding Notes | AM3: Target Selling Price | AN3: Minimum Selling Price | AO3: Current Advertised Price | AP3: Expected Gross Profit | AQ3: Expected Margin % | AR3: Current Location | AS3: Stock Status | AT3: Date Sold | AU3: Actual Selling Price | AV3: Actual Gross Profit | AW3: Actual Margin % | AX3: Salesperson | AY3: Customer/Invoice Ref | AZ3: Payment Method | BA3: Photo/Document Link | BB3: Notes
A4: WAT-0001 | C4: BC100001 | D4: 46037 | E4: Watch | F4: Luxury Watch | G4: Rolex | H4: Submariner | I4: 126610LN | J4: ROL123456 | K4: Rolex Submariner Date 41mm, black dial | T4: 41mm | U4: Automatic | V4: 2022 | W4: Yes | X4: Yes | Y4: Yes | Z4: Excellent | AA4: Prestige Watch Co | AB4: Watch Dealer | AC4: PWC-4471 | AD4: GBP | AE4: 8000 | AG4: =IF($AE4="","",$AE4*IF($AD4="GBP",1,IF($AF4<>"",$AF4,IFERROR(INDEX(SETTINGS!$W$29:$W$36,MATCH($AD4,SETTINGS!$V$29:$V$36,0)),1)))) -> 8000 | AH4: 100 | AI4: =IF(N($AG4)+N($AH4)=0,"",N($AG4)+N($AH4)) -> 8100 | AJ4: Partner 1 | AK4: Partner Loan | AL4: EXAMPLE – funded personally by Partner 1; business owes reimbursement | AM4: 10500 | AN4: 9500 | AO4: 10500 | AP4: =IF(OR($AM4="",$AI4=""),"",$AM4-$AI4) -> 2400 | AQ4: =IF(OR($AM4="",$AM4=0,$AP4=""),"",$AP4/$AM4) -> 0.22857143 | AR4: Shop Safe | AS4: Sold | AT4: 46063 | AU4: 10200 | AV4: =IF(OR($AU4="",$AI4=""),"",$AU4-$AI4) -> 2100 | AW4: =IF(OR($AU4="",$AU4=0,$AV4=""),"",$AV4/$AU4) -> 0.20588235 | AX4: Sarah Hughes | AY4: INV-1001 | AZ4: Bank Transfer | BA4: link/wat-0001.jpg | BB4: EXAMPLE ROW – safe to delete
A5: JWL-0001 | C5: BC200001 | D5: 46042 | E5: Diamond Jewellery | F5: Solitaire Ring | G5: Bespoke | H5: Solitaire | K5: Platinum solitaire diamond ring 1.01ct | L5: Platinum | M5: 950 Platinum | N5: 5.2 | O5: Diamond | P5: 1.01 | Q5: F | R5: VS1 | S5: M | Z5: New | AA5: Hatton Diamonds | AB5: Jewellery Dealer | AC5: HD-9987 | AD5: GBP | AE5: 3500 | AG5: =IF($AE5="","",$AE5*IF($AD5="GBP",1,IF($AF5<>"",$AF5,IFERROR(INDEX(SETTINGS!$W$29:$W$36,MATCH($AD5,SETTINGS!$V$29:$V$36,0)),1)))) -> 3500 | AH5: 50 | AI5: =IF(N($AG5)+N($AH5)=0,"",N($AG5)+N($AH5)) -> 3550 | AJ5: Partner 2 | AK5: Partner Loan | AL5: EXAMPLE – funded personally by Partner 2 | AM5: 5500 | AN5: 4800 | AO5: 5500 | AP5: =IF(OR($AM5="",$AI5=""),"",$AM5-$AI5) -> 1950 | AQ5: =IF(OR($AM5="",$AM5=0,$AP5=""),"",$AP5/$AM5) -> 0.35454545 | AR5: Shop Display | AS5: Available | AV5: =IF(OR($AU5="",$AI5=""),"",$AU5-$AI5) | AW5: =IF(OR($AU5="",$AU5=0,$AV5=""),"",$AV5/$AU5) | BA5: link/jwl-0001.jpg | BB5: EXAMPLE ROW – safe to delete
A6: WAT-0002 | C6: BC100002 | D6: 46047 | E6: Watch | F6: Luxury Watch | G6: Omega | H6: Speedmaster | I6: 310.30.42 | J6: OMG789012 | K6: Omega Speedmaster Moonwatch 42mm | T6: 42mm | U6: Manual | V6: 2023 | W6: Yes | X6: No | Y6: No | Z6: Very Good | AA6: City Auctions | AB6: Auction | AC6: CA-2201 | AD6: USD | AE6: 4000 | AF6: 0.79 | AG6: =IF($AE6="","",$AE6*IF($AD6="GBP",1,IF($AF6<>"",$AF6,IFERROR(INDEX(SETTINGS!$W$29:$W$36,MATCH($AD6,SETTINGS!$V$29:$V$36,0)),1)))) -> 3160 | AH6: 40 | AI6: =IF(N($AG6)+N($AH6)=0,"",N($AG6)+N($AH6)) -> 3200 | AJ6: Business Bank Account | AK6: Business Purchase | AL6: EXAMPLE – bought in US Dollars ($4,000 × 0.79 = £3,160) | AM6: 4500 | AN6: 4000 | AO6: 4500 | AP6: =IF(OR($AM6="",$AI6=""),"",$AM6-$AI6) -> 1300 | AQ6: =IF(OR($AM6="",$AM6=0,$AP6=""),"",$AP6/$AM6) -> 0.28888889 | AR6: Shop Display | AS6: Available | AV6: =IF(OR($AU6="",$AI6=""),"",$AU6-$AI6) | AW6: =IF(OR($AU6="",$AU6=0,$AV6=""),"",$AV6/$AU6) | BA6: link/wat-0002.jpg | BB6: EXAMPLE ROW – safe to delete
A7: JWL-0002 | C7: BC200002 | D7: 46054 | E7: Gold | F7: Chain Necklace | H7: Belcher Chain | K7: 18ct yellow gold belcher chain necklace | L7: Gold | M7: 18ct | N7: 22.5 | Z7: New | AA7: Goldsmith Wholesale | AB7: Wholesaler | AC7: GW-5540 | AD7: GBP | AE7: 1500 | AG7: =IF($AE7="","",$AE7*IF($AD7="GBP",1,IF($AF7<>"",$AF7,IFERROR(INDEX(SETTINGS!$W$29:$W$36,MATCH($AD7,SETTINGS!$V$29:$V$36,0)),1)))) -> 1500 | AH7: 0 | AI7: =IF(N($AG7)+N($AH7)=0,"",N($AG7)+N($AH7)) -> 1500 | AJ7: Business Bank Account | AK7: Business Purchase | AL7: EXAMPLE – business owned stock | AM7: 2200 | AN7: 1900 | AO7: 2200 | AP7: =IF(OR($AM7="",$AI7=""),"",$AM7-$AI7) -> 700 | AQ7: =IF(OR($AM7="",$AM7=0,$AP7=""),"",$AP7/$AM7) -> 0.31818182 | AR7: Shop Safe | AS7: Available | AV7: =IF(OR($AU7="",$AI7=""),"",$AU7-$AI7) | AW7: =IF(OR($AU7="",$AU7=0,$AV7=""),"",$AV7/$AU7) | BA7: link/jwl-0002.jpg | BB7: EXAMPLE ROW – safe to delete
A8: WAT-0003 | C8: BC100003 | D8: 46058 | E8: Watch | F8: Luxury Watch | G8: Cartier | H8: Santos | I8: WSSA0018 | J8: CAR334455 | K8: Cartier Santos Medium steel | T8: 35mm | U8: Automatic | V8: 2021 | W8: Yes | X8: Yes | Y8: Yes | Z8: Excellent | AA8: Private Seller | AB8: Private Seller | AC8: PS-0007 | AD8: AED | AE8: 22000 | AF8: 0.215 | AG8: =IF($AE8="","",$AE8*IF($AD8="GBP",1,IF($AF8<>"",$AF8,IFERROR(INDEX(SETTINGS!$W$29:$W$36,MATCH($AD8,SETTINGS!$V$29:$V$36,0)),1)))) -> 4730 | AH8: 60 | AI8: =IF(N($AG8)+N($AH8)=0,"",N($AG8)+N($AH8)) -> 4790 | AJ8: Partner 3 | AK8: Partner Loan | AL8: EXAMPLE – bought in UAE Dirham (22,000 AED × 0.215 = £4,730); with Partner 3 | AM8: 6500 | AN8: 5900 | AO8: 6500 | AP8: =IF(OR($AM8="",$AI8=""),"",$AM8-$AI8) -> 1710 | AQ8: =IF(OR($AM8="",$AM8=0,$AP8=""),"",$AP8/$AM8) -> 0.26307692 | AR8: Partner 3 | AS8: With Partner | AV8: =IF(OR($AU8="",$AI8=""),"",$AU8-$AI8) | AW8: =IF(OR($AU8="",$AU8=0,$AV8=""),"",$AV8/$AU8) | BB8: EXAMPLE ROW – safe to delete
A9: JWL-0003 | C9: BC200003 | D9: 46063 | E9: Bracelet | F9: Bangle | H9: Gold Bangle | K9: 22ct gold hand bracelet / bangle | L9: Gold | M9: 22ct | N9: 18 | O9: None | Z9: New | AA9: Goldsmith Wholesale | AB9: Wholesaler | AC9: GW-5541 | AD9: GBP | AE9: 1650 | AG9: =IF($AE9="","",$AE9*IF($AD9="GBP",1,IF($AF9<>"",$AF9,IFERROR(INDEX(SETTINGS!$W$29:$W$36,MATCH($AD9,SETTINGS!$V$29:$V$36,0)),1)))) -> 1650 | AH9: 0 | AI9: =IF(N($AG9)+N($AH9)=0,"",N($AG9)+N($AH9)) -> 1650 | AJ9: Business Bank Account | AK9: Business Purchase | AL9: EXAMPLE – gold bangle; use Jewellery Details for the gold calculator | AM9: 2400 | AN9: 2050 | AO9: 2400 | AP9: =IF(OR($AM9="",$AI9=""),"",$AM9-$AI9) -> 750 | AQ9: =IF(OR($AM9="",$AM9=0,$AP9=""),"",$AP9/$AM9) -> 0.3125 | AR9: Shop Safe | AS9: Available | AV9: =IF(OR($AU9="",$AI9=""),"",$AU9-$AI9) | AW9: =IF(OR($AU9="",$AU9=0,$AV9=""),"",$AV9/$AU9) | BA9: link/jwl-0003.jpg | BB9: EXAMPLE bracelet – safe to delete
AG10: =IF($AE10="","",$AE10*IF($AD10="GBP",1,IF($AF10<>"",$AF10,IFERROR(INDEX(SETTINGS!$W$29:$W$36,MATCH($AD10,SETTINGS!$V$29:$V$36,0)),1)))) | AI10: =IF(N($AG10)+N($AH10)=0,"",N($AG10)+N($AH10)) | AP10: =IF(OR($AM10="",$AI10=""),"",$AM10-$AI10) | AQ10: =IF(OR($AM10="",$AM10=0,$AP10=""),"",$AP10/$AM10) | AV10: =IF(OR($AU10="",$AI10=""),"",$AU10-$AI10) | AW10: =IF(OR($AU10="",$AU10=0,$AV10=""),"",$AV10/$AU10)
AG11: =IF($AE11="","",$AE11*IF($AD11="GBP",1,IF($AF11<>"",$AF11,IFERROR(INDEX(SETTINGS!$W$29:$W$36,MATCH($AD11,SETTINGS!$V$29:$V$36,0)),1)))) | AI11: =IF(N($AG11)+N($AH11)=0,"",N($AG11)+N($AH11)) | AP11: =IF(OR($AM11="",$AI11=""),"",$AM11-$AI11) | AQ11: =IF(OR($AM11="",$AM11=0,$AP11=""),"",$AP11/$AM11) | AV11: =IF(OR($AU11="",$AI11=""),"",$AU11-$AI11) | AW11: =IF(OR($AU11="",$AU11=0,$AV11=""),"",$AV11/$AU11)
AG12: =IF($AE12="","",$AE12*IF($AD12="GBP",1,IF($AF12<>"",$AF12,IFERROR(INDEX(SETTINGS!$W$29:$W$36,MATCH($AD12,SETTINGS!$V$29:$V$36,0)),1)))) | AI12: =IF(N($AG12)+N($AH12)=0,"",N($AG12)+N($AH12)) | AP12: =IF(OR($AM12="",$AI12=""),"",$AM12-$AI12) | AQ12: =IF(OR($AM12="",$AM12=0,$AP12=""),"",$AP12/$AM12) | AV12: =IF(OR($AU12="",$AI12=""),"",$AU12-$AI12) | AW12: =IF(OR($AU12="",$AU12=0,$AV12=""),"",$AV12/$AU12)
AG13: =IF($AE13="","",$AE13*IF($AD13="GBP",1,IF($AF13<>"",$AF13,IFERROR(INDEX(SETTINGS!$W$29:$W$36,MATCH($AD13,SETTINGS!$V$29:$V$36,0)),1)))) | AI13: =IF(N($AG13)+N($AH13)=0,"",N($AG13)+N($AH13)) | AP13: =IF(OR($AM13="",$AI13=""),"",$AM13-$AI13) | AQ13: =IF(OR($AM13="",$AM13=0,$AP13=""),"",$AP13/$AM13) | AV13: =IF(OR($AU13="",$AI13=""),"",$AU13-$AI13) | AW13: =IF(OR($AU13="",$AU13=0,$AV13=""),"",$AV13/$AU13)
AG14: =IF($AE14="","",$AE14*IF($AD14="GBP",1,IF($AF14<>"",$AF14,IFERROR(INDEX(SETTINGS!$W$29:$W$36,MATCH($AD14,SETTINGS!$V$29:$V$36,0)),1)))) | AI14: =IF(N($AG14)+N($AH14)=0,"",N($AG14)+N($AH14)) | AP14: =IF(OR($AM14="",$AI14=""),"",$AM14-$AI14) | AQ14: =IF(OR($AM14="",$AM14=0,$AP14=""),"",$AP14/$AM14) | AV14: =IF(OR($AU14="",$AI14=""),"",$AU14-$AI14) | AW14: =IF(OR($AU14="",$AU14=0,$AV14=""),"",$AV14/$AU14)
AG15: =IF($AE15="","",$AE15*IF($AD15="GBP",1,IF($AF15<>"",$AF15,IFERROR(INDEX(SETTINGS!$W$29:$W$36,MATCH($AD15,SETTINGS!$V$29:$V$36,0)),1)))) | AI15: =IF(N($AG15)+N($AH15)=0,"",N($AG15)+N($AH15)) | AP15: =IF(OR($AM15="",$AI15=""),"",$AM15-$AI15) | AQ15: =IF(OR($AM15="",$AM15=0,$AP15=""),"",$AP15/$AM15) | AV15: =IF(OR($AU15="",$AI15=""),"",$AU15-$AI15) | AW15: =IF(OR($AU15="",$AU15=0,$AV15=""),"",$AV15/$AU15)
AG16: =IF($AE16="","",$AE16*IF($AD16="GBP",1,IF($AF16<>"",$AF16,IFERROR(INDEX(SETTINGS!$W$29:$W$36,MATCH($AD16,SETTINGS!$V$29:$V$36,0)),1)))) | AI16: =IF(N($AG16)+N($AH16)=0,"",N($AG16)+N($AH16)) | AP16: =IF(OR($AM16="",$AI16=""),"",$AM16-$AI16) | AQ16: =IF(OR($AM16="",$AM16=0,$AP16=""),"",$AP16/$AM16) | AV16: =IF(OR($AU16="",$AI16=""),"",$AU16-$AI16) | AW16: =IF(OR($AU16="",$AU16=0,$AV16=""),"",$AV16/$AU16)
AG17: =IF($AE17="","",$AE17*IF($AD17="GBP",1,IF($AF17<>"",$AF17,IFERROR(INDEX(SETTINGS!$W$29:$W$36,MATCH($AD17,SETTINGS!$V$29:$V$36,0)),1)))) | AI17: =IF(N($AG17)+N($AH17)=0,"",N($AG17)+N($AH17)) | AP17: =IF(OR($AM17="",$AI17=""),"",$AM17-$AI17) | AQ17: =IF(OR($AM17="",$AM17=0,$AP17=""),"",$AP17/$AM17) | AV17: =IF(OR($AU17="",$AI17=""),"",$AU17-$AI17) | AW17: =IF(OR($AU17="",$AU17=0,$AV17=""),"",$AV17/$AU17)
AG18: =IF($AE18="","",$AE18*IF($AD18="GBP",1,IF($AF18<>"",$AF18,IFERROR(INDEX(SETTINGS!$W$29:$W$36,MATCH($AD18,SETTINGS!$V$29:$V$36,0)),1)))) | AI18: =IF(N($AG18)+N($AH18)=0,"",N($AG18)+N($AH18)) | AP18: =IF(OR($AM18="",$AI18=""),"",$AM18-$AI18) | AQ18: =IF(OR($AM18="",$AM18=0,$AP18=""),"",$AP18/$AM18) | AV18: =IF(OR($AU18="",$AI18=""),"",$AU18-$AI18) | AW18: =IF(OR($AU18="",$AU18=0,$AV18=""),"",$AV18/$AU18)
AG19: =IF($AE19="","",$AE19*IF($AD19="GBP",1,IF($AF19<>"",$AF19,IFERROR(INDEX(SETTINGS!$W$29:$W$36,MATCH($AD19,SETTINGS!$V$29:$V$36,0)),1)))) | AI19: =IF(N($AG19)+N($AH19)=0,"",N($AG19)+N($AH19)) | AP19: =IF(OR($AM19="",$AI19=""),"",$AM19-$AI19) | AQ19: =IF(OR($AM19="",$AM19=0,$AP19=""),"",$AP19/$AM19) | AV19: =IF(OR($AU19="",$AI19=""),"",$AU19-$AI19) | AW19: =IF(OR($AU19="",$AU19=0,$AV19=""),"",$AV19/$AU19)
AG20: =IF($AE20="","",$AE20*IF($AD20="GBP",1,IF($AF20<>"",$AF20,IFERROR(INDEX(SETTINGS!$W$29:$W$36,MATCH($AD20,SETTINGS!$V$29:$V$36,0)),1)))) | AI20: =IF(N($AG20)+N($AH20)=0,"",N($AG20)+N($AH20)) | AP20: =IF(OR($AM20="",$AI20=""),"",$AM20-$AI20) | AQ20: =IF(OR($AM20="",$AM20=0,$AP20=""),"",$AP20/$AM20) | AV20: =IF(OR($AU20="",$AI20=""),"",$AU20-$AI20) | AW20: =IF(OR($AU20="",$AU20=0,$AV20=""),"",$AV20/$AU20)
AG21: =IF($AE21="","",$AE21*IF($AD21="GBP",1,IF($AF21<>"",$AF21,IFERROR(INDEX(SETTINGS!$W$29:$W$36,MATCH($AD21,SETTINGS!$V$29:$V$36,0)),1)))) | AI21: =IF(N($AG21)+N($AH21)=0,"",N($AG21)+N($AH21)) | AP21: =IF(OR($AM21="",$AI21=""),"",$AM21-$AI21) | AQ21: =IF(OR($AM21="",$AM21=0,$AP21=""),"",$AP21/$AM21) | AV21: =IF(OR($AU21="",$AI21=""),"",$AU21-$AI21) | AW21: =IF(OR($AU21="",$AU21=0,$AV21=""),"",$AV21/$AU21)
... AG63: =IF($AE63="","",$AE63*IF($AD63="GBP",1,IF($AF63<>"",$AF63,IFERROR(INDEX(SETTINGS!$W$29:$W$36,MATCH($AD63,SETTINGS!$V$29:$V$36,0)),1)))) | AI63: =IF(N($AG63)+N($AH63)=0,"",N($AG63)+N($AH63)) | AP63: =IF(OR($AM63="",$AI63=""),"",$AM63-$AI63) | AQ63: =IF(OR($AM63="",$AM63=0,$AP63=""),"",$AP63/$AM63) | AV63: =IF(OR($AU63="",$AI63=""),"",$AU63-$AI63) | AW63: =IF(OR($AU63="",$AU63=0,$AV63=""),"",$AV63/$AU63)

Sheet WATCH DETAILS
A1: WATCH DETAILS
A2: Watch-specific view. Enter a Stock ID (dropdown) — details pull automatically from Inventory Master. Cream fields are watch-only extras you can enter.
A3: Stock ID | B3: Brand | C3: Model | D3: Reference Number | E3: Serial Number | F3: Year | G3: Case Size | H3: Case Material | I3: Dial Colour | J3: Bracelet/Strap | K3: Movement | L3: Auto/Manual/Quartz | M3: Box | N3: Papers | O3: Warranty Card | P3: Warranty Date | Q3: Service History | R3: Last Service | S3: Condition | T3: Purchase Cost | U3: Target Price | V3: Current Price | W3: Status | X3: Location | Y3: Notes
A4: WAT-0001 | B4: =IF($A4="","",IFERROR(INDEX('INVENTORY MASTER'!$G$4:$G$63,MATCH($A4,'INVENTORY MASTER'!$A$4:$A$63,0)),"")) -> Rolex | C4: =IF($A4="","",IFERROR(INDEX('INVENTORY MASTER'!$H$4:$H$63,MATCH($A4,'INVENTORY MASTER'!$A$4:$A$63,0)),"")) -> Submariner | D4: =IF($A4="","",IFERROR(INDEX('INVENTORY MASTER'!$I$4:$I$63,MATCH($A4,'INVENTORY MASTER'!$A$4:$A$63,0)),"")) -> 126610LN | E4: =IF($A4="","",IFERROR(INDEX('INVENTORY MASTER'!$J$4:$J$63,MATCH($A4,'INVENTORY MASTER'!$A$4:$A$63,0)),"")) -> ROL123456 | F4: =IF($A4="","",IFERROR(INDEX('INVENTORY MASTER'!$V$4:$V$63,MATCH($A4,'INVENTORY MASTER'!$A$4:$A$63,0)),"")) -> 2022 | G4: =IF($A4="","",IFERROR(INDEX('INVENTORY MASTER'!$T$4:$T$63,MATCH($A4,'INVENTORY MASTER'!$A$4:$A$63,0)),"")) -> 41mm | K4: =IF($A4="","",IFERROR(INDEX('INVENTORY MASTER'!$U$4:$U$63,MATCH($A4,'INVENTORY MASTER'!$A$4:$A$63,0)),"")) -> Automatic | L4: =IF($A4="","",IFERROR(INDEX('INVENTORY MASTER'!$U$4:$U$63,MATCH($A4,'INVENTORY MASTER'!$A$4:$A$63,0)),"")) -> Automatic | M4: =IF($A4="","",IFERROR(INDEX('INVENTORY MASTER'!$W$4:$W$63,MATCH($A4,'INVENTORY MASTER'!$A$4:$A$63,0)),"")) -> Yes | N4: =IF($A4="","",IFERROR(INDEX('INVENTORY MASTER'!$X$4:$X$63,MATCH($A4,'INVENTORY MASTER'!$A$4:$A$63,0)),"")) -> Yes | O4: =IF($A4="","",IFERROR(INDEX('INVENTORY MASTER'!$Y$4:$Y$63,MATCH($A4,'INVENTORY MASTER'!$A$4:$A$63,0)),"")) -> Yes | S4: =IF($A4="","",IFERROR(INDEX('INVENTORY MASTER'!$Z$4:$Z$63,MATCH($A4,'INVENTORY MASTER'!$A$4:$A$63,0)),"")) -> Excellent | T4: =IF($A4="","",IFERROR(INDEX('INVENTORY MASTER'!$AI$4:$AI$63,MATCH($A4,'INVENTORY MASTER'!$A$4:$A$63,0)),"")) -> 8100 | U4: =IF($A4="","",IFERROR(INDEX('INVENTORY MASTER'!$AM$4:$AM$63,MATCH($A4,'INVENTORY MASTER'!$A$4:$A$63,0)),"")) -> 10500 | V4: =IF($A4="","",IFERROR(INDEX('INVENTORY MASTER'!$AO$4:$AO$63,MATCH($A4,'INVENTORY MASTER'!$A$4:$A$63,0)),"")) -> 10500 | W4: =IF($A4="","",IFERROR(INDEX('INVENTORY MASTER'!$AS$4:$AS$63,MATCH($A4,'INVENTORY MASTER'!$A$4:$A$63,0)),"")) -> Sold | X4: =IF($A4="","",IFERROR(INDEX('INVENTORY MASTER'!$AR$4:$AR$63,MATCH($A4,'INVENTORY MASTER'!$A$4:$A$63,0)),"")) -> Shop Safe
A5: WAT-0002 | B5: =IF($A5="","",IFERROR(INDEX('INVENTORY MASTER'!$G$4:$G$63,MATCH($A5,'INVENTORY MASTER'!$A$4:$A$63,0)),"")) -> Omega | C5: =IF($A5="","",IFERROR(INDEX('INVENTORY MASTER'!$H$4:$H$63,MATCH($A5,'INVENTORY MASTER'!$A$4:$A$63,0)),"")) -> Speedmaster | D5: =IF($A5="","",IFERROR(INDEX('INVENTORY MASTER'!$I$4:$I$63,MATCH($A5,'INVENTORY MASTER'!$A$4:$A$63,0)),"")) -> 310.30.42 | E5: =IF($A5="","",IFERROR(INDEX('INVENTORY MASTER'!$J$4:$J$63,MATCH($A5,'INVENTORY MASTER'!$A$4:$A$63,0)),"")) -> OMG789012 | F5: =IF($A5="","",IFERROR(INDEX('INVENTORY MASTER'!$V$4:$V$63,MATCH($A5,'INVENTORY MASTER'!$A$4:$A$63,0)),"")) -> 2023 | G5: =IF($A5="","",IFERROR(INDEX('INVENTORY MASTER'!$T$4:$T$63,MATCH($A5,'INVENTORY MASTER'!$A$4:$A$63,0)),"")) -> 42mm | K5: =IF($A5="","",IFERROR(INDEX('INVENTORY MASTER'!$U$4:$U$63,MATCH($A5,'INVENTORY MASTER'!$A$4:$A$63,0)),"")) -> Manual | L5: =IF($A5="","",IFERROR(INDEX('INVENTORY MASTER'!$U$4:$U$63,MATCH($A5,'INVENTORY MASTER'!$A$4:$A$63,0)),"")) -> Manual | M5: =IF($A5="","",IFERROR(INDEX('INVENTORY MASTER'!$W$4:$W$63,MATCH($A5,'INVENTORY MASTER'!$A$4:$A$63,0)),"")) -> Yes | N5: =IF($A5="","",IFERROR(INDEX('INVENTORY MASTER'!$X$4:$X$63,MATCH($A5,'INVENTORY MASTER'!$A$4:$A$63,0)),"")) -> No | O5: =IF($A5="","",IFERROR(INDEX('INVENTORY MASTER'!$Y$4:$Y$63,MATCH($A5,'INVENTORY MASTER'!$A$4:$A$63,0)),"")) -> No | S5: =IF($A5="","",IFERROR(INDEX('INVENTORY MASTER'!$Z$4:$Z$63,MATCH($A5,'INVENTORY MASTER'!$A$4:$A$63,0)),"")) -> Very Good | T5: =IF($A5="","",IFERROR(INDEX('INVENTORY MASTER'!$AI$4:$AI$63,MATCH($A5,'INVENTORY MASTER'!$A$4:$A$63,0)),"")) -> 3200 | U5: =IF($A5="","",IFERROR(INDEX('INVENTORY MASTER'!$AM$4:$AM$63,MATCH($A5,'INVENTORY MASTER'!$A$4:$A$63,0)),"")) -> 4500 | V5: =IF($A5="","",IFERROR(INDEX('INVENTORY MASTER'!$AO$4:$AO$63,MATCH($A5,'INVENTORY MASTER'!$A$4:$A$63,0)),"")) -> 4500 | W5: =IF($A5="","",IFERROR(INDEX('INVENTORY MASTER'!$AS$4:$AS$63,MATCH($A5,'INVENTORY MASTER'!$A$4:$A$63,0)),"")) -> Available | X5: =IF($A5="","",IFERROR(INDEX('INVENTORY MASTER'!$AR$4:$AR$63,MATCH($A5,'INVENTORY MASTER'!$A$4:$A$63,0)),"")) -> Shop Display
A6: WAT-0003 | B6: =IF($A6="","",IFERROR(INDEX('INVENTORY MASTER'!$G$4:$G$63,MATCH($A6,'INVENTORY MASTER'!$A$4:$A$63,0)),"")) -> Cartier | C6: =IF($A6="","",IFERROR(INDEX('INVENTORY MASTER'!$H$4:$H$63,MATCH($A6,'INVENTORY MASTER'!$A$4:$A$63,0)),"")) -> Santos | D6: =IF($A6="","",IFERROR(INDEX('INVENTORY MASTER'!$I$4:$I$63,MATCH($A6,'INVENTORY MASTER'!$A$4:$A$63,0)),"")) -> WSSA0018 | E6: =IF($A6="","",IFERROR(INDEX('INVENTORY MASTER'!$J$4:$J$63,MATCH($A6,'INVENTORY MASTER'!$A$4:$A$63,0)),"")) -> CAR334455 | F6: =IF($A6="","",IFERROR(INDEX('INVENTORY MASTER'!$V$4:$V$63,MATCH($A6,'INVENTORY MASTER'!$A$4:$A$63,0)),"")) -> 2021 | G6: =IF($A6="","",IFERROR(INDEX('INVENTORY MASTER'!$T$4:$T$63,MATCH($A6,'INVENTORY MASTER'!$A$4:$A$63,0)),"")) -> 35mm | K6: =IF($A6="","",IFERROR(INDEX('INVENTORY MASTER'!$U$4:$U$63,MATCH($A6,'INVENTORY MASTER'!$A$4:$A$63,0)),"")) -> Automatic | L6: =IF($A6="","",IFERROR(INDEX('INVENTORY MASTER'!$U$4:$U$63,MATCH($A6,'INVENTORY MASTER'!$A$4:$A$63,0)),"")) -> Automatic | M6: =IF($A6="","",IFERROR(INDEX('INVENTORY MASTER'!$W$4:$W$63,MATCH($A6,'INVENTORY MASTER'!$A$4:$A$63,0)),"")) -> Yes | N6: =IF($A6="","",IFERROR(INDEX('INVENTORY MASTER'!$X$4:$X$63,MATCH($A6,'INVENTORY MASTER'!$A$4:$A$63,0)),"")) -> Yes | O6: =IF($A6="","",IFERROR(INDEX('INVENTORY MASTER'!$Y$4:$Y$63,MATCH($A6,'INVENTORY MASTER'!$A$4:$A$63,0)),"")) -> Yes | S6: =IF($A6="","",IFERROR(INDEX('INVENTORY MASTER'!$Z$4:$Z$63,MATCH($A6,'INVENTORY MASTER'!$A$4:$A$63,0)),"")) -> Excellent | T6: =IF($A6="","",IFERROR(INDEX('INVENTORY MASTER'!$AI$4:$AI$63,MATCH($A6,'INVENTORY MASTER'!$A$4:$A$63,0)),"")) -> 4790 | U6: =IF($A6="","",IFERROR(INDEX('INVENTORY MASTER'!$AM$4:$AM$63,MATCH($A6,'INVENTORY MASTER'!$A$4:$A$63,0)),"")) -> 6500 | V6: =IF($A6="","",IFERROR(INDEX('INVENTORY MASTER'!$AO$4:$AO$63,MATCH($A6,'INVENTORY MASTER'!$A$4:$A$63,0)),"")) -> 6500 | W6: =IF($A6="","",IFERROR(INDEX('INVENTORY MASTER'!$AS$4:$AS$63,MATCH($A6,'INVENTORY MASTER'!$A$4:$A$63,0)),"")) -> With Partner | X6: =IF($A6="","",IFERROR(INDEX('INVENTORY MASTER'!$AR$4:$AR$63,MATCH($A6,'INVENTORY MASTER'!$A$4:$A$63,0)),"")) -> Partner 3
B7: =IF($A7="","",IFERROR(INDEX('INVENTORY MASTER'!$G$4:$G$63,MATCH($A7,'INVENTORY MASTER'!$A$4:$A$63,0)),"")) | C7: =IF($A7="","",IFERROR(INDEX('INVENTORY MASTER'!$H$4:$H$63,MATCH($A7,'INVENTORY MASTER'!$A$4:$A$63,0)),"")) | D7: =IF($A7="","",IFERROR(INDEX('INVENTORY MASTER'!$I$4:$I$63,MATCH($A7,'INVENTORY MASTER'!$A$4:$A$63,0)),"")) | E7: =IF($A7="","",IFERROR(INDEX('INVENTORY MASTER'!$J$4:$J$63,MATCH($A7,'INVENTORY MASTER'!$A$4:$A$63,0)),"")) | F7: =IF($A7="","",IFERROR(INDEX('INVENTORY MASTER'!$V$4:$V$63,MATCH($A7,'INVENTORY MASTER'!$A$4:$A$63,0)),"")) | G7: =IF($A7="","",IFERROR(INDEX('INVENTORY MASTER'!$T$4:$T$63,MATCH($A7,'INVENTORY MASTER'!$A$4:$A$63,0)),"")) | K7: =IF($A7="","",IFERROR(INDEX('INVENTORY MASTER'!$U$4:$U$63,MATCH($A7,'INVENTORY MASTER'!$A$4:$A$63,0)),"")) | L7: =IF($A7="","",IFERROR(INDEX('INVENTORY MASTER'!$U$4:$U$63,MATCH($A7,'INVENTORY MASTER'!$A$4:$A$63,0)),"")) | M7: =IF($A7="","",IFERROR(INDEX('INVENTORY MASTER'!$W$4:$W$63,MATCH($A7,'INVENTORY MASTER'!$A$4:$A$63,0)),"")) | N7: =IF($A7="","",IFERROR(INDEX('INVENTORY MASTER'!$X$4:$X$63,MATCH($A7,'INVENTORY MASTER'!$A$4:$A$63,0)),"")) | O7: =IF($A7="","",IFERROR(INDEX('INVENTORY MASTER'!$Y$4:$Y$63,MATCH($A7,'INVENTORY MASTER'!$A$4:$A$63,0)),"")) | S7: =IF($A7="","",IFERROR(INDEX('INVENTORY MASTER'!$Z$4:$Z$63,MATCH($A7,'INVENTORY MASTER'!$A$4:$A$63,0)),"")) | T7: =IF($A7="","",IFERROR(INDEX('INVENTORY MASTER'!$AI$4:$AI$63,MATCH($A7,'INVENTORY MASTER'!$A$4:$A$63,0)),"")) | U7: =IF($A7="","",IFERROR(INDEX('INVENTORY MASTER'!$AM$4:$AM$63,MATCH($A7,'INVENTORY MASTER'!$A$4:$A$63,0)),"")) | V7: =IF($A7="","",IFERROR(INDEX('INVENTORY MASTER'!$AO$4:$AO$63,MATCH($A7,'INVENTORY MASTER'!$A$4:$A$63,0)),"")) | W7: =IF($A7="","",IFERROR(INDEX('INVENTORY MASTER'!$AS$4:$AS$63,MATCH($A7,'INVENTORY MASTER'!$A$4:$A$63,0)),"")) | X7: =IF($A7="","",IFERROR(INDEX('INVENTORY MASTER'!$AR$4:$AR$63,MATCH($A7,'INVENTORY MASTER'!$A$4:$A$63,0)),""))
B8: =IF($A8="","",IFERROR(INDEX('INVENTORY MASTER'!$G$4:$G$63,MATCH($A8,'INVENTORY MASTER'!$A$4:$A$63,0)),"")) | C8: =IF($A8="","",IFERROR(INDEX('INVENTORY MASTER'!$H$4:$H$63,MATCH($A8,'INVENTORY MASTER'!$A$4:$A$63,0)),"")) | D8: =IF($A8="","",IFERROR(INDEX('INVENTORY MASTER'!$I$4:$I$63,MATCH($A8,'INVENTORY MASTER'!$A$4:$A$63,0)),"")) | E8: =IF($A8="","",IFERROR(INDEX('INVENTORY MASTER'!$J$4:$J$63,MATCH($A8,'INVENTORY MASTER'!$A$4:$A$63,0)),"")) | F8: =IF($A8="","",IFERROR(INDEX('INVENTORY MASTER'!$V$4:$V$63,MATCH($A8,'INVENTORY MASTER'!$A$4:$A$63,0)),"")) | G8: =IF($A8="","",IFERROR(INDEX('INVENTORY MASTER'!$T$4:$T$63,MATCH($A8,'INVENTORY MASTER'!$A$4:$A$63,0)),"")) | K8: =IF($A8="","",IFERROR(INDEX('INVENTORY MASTER'!$U$4:$U$63,MATCH($A8,'INVENTORY MASTER'!$A$4:$A$63,0)),"")) | L8: =IF($A8="","",IFERROR(INDEX('INVENTORY MASTER'!$U$4:$U$63,MATCH($A8,'INVENTORY MASTER'!$A$4:$A$63,0)),"")) | M8: =IF($A8="","",IFERROR(INDEX('INVENTORY MASTER'!$W$4:$W$63,MATCH($A8,'INVENTORY MASTER'!$A$4:$A$63,0)),"")) | N8: =IF($A8="","",IFERROR(INDEX('INVENTORY MASTER'!$X$4:$X$63,MATCH($A8,'INVENTORY MASTER'!$A$4:$A$63,0)),"")) | O8: =IF($A8="","",IFERROR(INDEX('INVENTORY MASTER'!$Y$4:$Y$63,MATCH($A8,'INVENTORY MASTER'!$A$4:$A$63,0)),"")) | S8: =IF($A8="","",IFERROR(INDEX('INVENTORY MASTER'!$Z$4:$Z$63,MATCH($A8,'INVENTORY MASTER'!$A$4:$A$63,0)),"")) | T8: =IF($A8="","",IFERROR(INDEX('INVENTORY MASTER'!$AI$4:$AI$63,MATCH($A8,'INVENTORY MASTER'!$A$4:$A$63,0)),"")) | U8: =IF($A8="","",IFERROR(INDEX('INVENTORY MASTER'!$AM$4:$AM$63,MATCH($A8,'INVENTORY MASTER'!$A$4:$A$63,0)),"")) | V8: =IF($A8="","",IFERROR(INDEX('INVENTORY MASTER'!$AO$4:$AO$63,MATCH($A8,'INVENTORY MASTER'!$A$4:$A$63,0)),"")) | W8: =IF($A8="","",IFERROR(INDEX('INVENTORY MASTER'!$AS$4:$AS$63,MATCH($A8,'INVENTORY MASTER'!$A$4:$A$63,0)),"")) | X8: =IF($A8="","",IFERROR(INDEX('INVENTORY MASTER'!$AR$4:$AR$63,MATCH($A8,'INVENTORY MASTER'!$A$4:$A$63,0)),""))
B9: =IF($A9="","",IFERROR(INDEX('INVENTORY MASTER'!$G$4:$G$63,MATCH($A9,'INVENTORY MASTER'!$A$4:$A$63,0)),"")) | C9: =IF($A9="","",IFERROR(INDEX('INVENTORY MASTER'!$H$4:$H$63,MATCH($A9,'INVENTORY MASTER'!$A$4:$A$63,0)),"")) | D9: =IF($A9="","",IFERROR(INDEX('INVENTORY MASTER'!$I$4:$I$63,MATCH($A9,'INVENTORY MASTER'!$A$4:$A$63,0)),"")) | E9: =IF($A9="","",IFERROR(INDEX('INVENTORY MASTER'!$J$4:$J$63,MATCH($A9,'INVENTORY MASTER'!$A$4:$A$63,0)),"")) | F9: =IF($A9="","",IFERROR(INDEX('INVENTORY MASTER'!$V$4:$V$63,MATCH($A9,'INVENTORY MASTER'!$A$4:$A$63,0)),"")) | G9: =IF($A9="","",IFERROR(INDEX('INVENTORY MASTER'!$T$4:$T$63,MATCH($A9,'INVENTORY MASTER'!$A$4:$A$63,0)),"")) | K9: =IF($A9="","",IFERROR(INDEX('INVENTORY MASTER'!$U$4:$U$63,MATCH($A9,'INVENTORY MASTER'!$A$4:$A$63,0)),"")) | L9: =IF($A9="","",IFERROR(INDEX('INVENTORY MASTER'!$U$4:$U$63,MATCH($A9,'INVENTORY MASTER'!$A$4:$A$63,0)),"")) | M9: =IF($A9="","",IFERROR(INDEX('INVENTORY MASTER'!$W$4:$W$63,MATCH($A9,'INVENTORY MASTER'!$A$4:$A$63,0)),"")) | N9: =IF($A9="","",IFERROR(INDEX('INVENTORY MASTER'!$X$4:$X$63,MATCH($A9,'INVENTORY MASTER'!$A$4:$A$63,0)),"")) | O9: =IF($A9="","",IFERROR(INDEX('INVENTORY MASTER'!$Y$4:$Y$63,MATCH($A9,'INVENTORY MASTER'!$A$4:$A$63,0)),"")) | S9: =IF($A9="","",IFERROR(INDEX('INVENTORY MASTER'!$Z$4:$Z$63,MATCH($A9,'INVENTORY MASTER'!$A$4:$A$63,0)),"")) | T9: =IF($A9="","",IFERROR(INDEX('INVENTORY MASTER'!$AI$4:$AI$63,MATCH($A9,'INVENTORY MASTER'!$A$4:$A$63,0)),"")) | U9: =IF($A9="","",IFERROR(INDEX('INVENTORY MASTER'!$AM$4:$AM$63,MATCH($A9,'INVENTORY MASTER'!$A$4:$A$63,0)),"")) | V9: =IF($A9="","",IFERROR(INDEX('INVENTORY MASTER'!$AO$4:$AO$63,MATCH($A9,'INVENTORY MASTER'!$A$4:$A$63,0)),"")) | W9: =IF($A9="","",IFERROR(INDEX('INVENTORY MASTER'!$AS$4:$AS$63,MATCH($A9,'INVENTORY MASTER'!$A$4:$A$63,0)),"")) | X9: =IF($A9="","",IFERROR(INDEX('INVENTORY MASTER'!$AR$4:$AR$63,MATCH($A9,'INVENTORY MASTER'!$A$4:$A$63,0)),""))
B10: =IF($A10="","",IFERROR(INDEX('INVENTORY MASTER'!$G$4:$G$63,MATCH($A10,'INVENTORY MASTER'!$A$4:$A$63,0)),"")) | C10: =IF($A10="","",IFERROR(INDEX('INVENTORY MASTER'!$H$4:$H$63,MATCH($A10,'INVENTORY MASTER'!$A$4:$A$63,0)),"")) | D10: =IF($A10="","",IFERROR(INDEX('INVENTORY MASTER'!$I$4:$I$63,MATCH($A10,'INVENTORY MASTER'!$A$4:$A$63,0)),"")) | E10: =IF($A10="","",IFERROR(INDEX('INVENTORY MASTER'!$J$4:$J$63,MATCH($A10,'INVENTORY MASTER'!$A$4:$A$63,0)),"")) | F10: =IF($A10="","",IFERROR(INDEX('INVENTORY MASTER'!$V$4:$V$63,MATCH($A10,'INVENTORY MASTER'!$A$4:$A$63,0)),"")) | G10: =IF($A10="","",IFERROR(INDEX('INVENTORY MASTER'!$T$4:$T$63,MATCH($A10,'INVENTORY MASTER'!$A$4:$A$63,0)),"")) | K10: =IF($A10="","",IFERROR(INDEX('INVENTORY MASTER'!$U$4:$U$63,MATCH($A10,'INVENTORY MASTER'!$A$4:$A$63,0)),"")) | L10: =IF($A10="","",IFERROR(INDEX('INVENTORY MASTER'!$U$4:$U$63,MATCH($A10,'INVENTORY MASTER'!$A$4:$A$63,0)),"")) | M10: =IF($A10="","",IFERROR(INDEX('INVENTORY MASTER'!$W$4:$W$63,MATCH($A10,'INVENTORY MASTER'!$A$4:$A$63,0)),"")) | N10: =IF($A10="","",IFERROR(INDEX('INVENTORY MASTER'!$X$4:$X$63,MATCH($A10,'INVENTORY MASTER'!$A$4:$A$63,0)),"")) | O10: =IF($A10="","",IFERROR(INDEX('INVENTORY MASTER'!$Y$4:$Y$63,MATCH($A10,'INVENTORY MASTER'!$A$4:$A$63,0)),"")) | S10: =IF($A10="","",IFERROR(INDEX('INVENTORY MASTER'!$Z$4:$Z$63,MATCH($A10,'INVENTORY MASTER'!$A$4:$A$63,0)),"")) | T10: =IF($A10="","",IFERROR(INDEX('INVENTORY MASTER'!$AI$4:$AI$63,MATCH($A10,'INVENTORY MASTER'!$A$4:$A$63,0)),"")) | U10: =IF($A10="","",IFERROR(INDEX('INVENTORY MASTER'!$AM$4:$AM$63,MATCH($A10,'INVENTORY MASTER'!$A$4:$A$63,0)),"")) | V10: =IF($A10="","",IFERROR(INDEX('INVENTORY MASTER'!$AO$4:$AO$63,MATCH($A10,'INVENTORY MASTER'!$A$4:$A$63,0)),"")) | W10: =IF($A10="","",IFERROR(INDEX('INVENTORY MASTER'!$AS$4:$AS$63,MATCH($A10,'INVENTORY MASTER'!$A$4:$A$63,0)),"")) | X10: =IF($A10="","",IFERROR(INDEX('INVENTORY MASTER'!$AR$4:$AR$63,MATCH($A10,'INVENTORY MASTER'!$A$4:$A$63,0)),""))
B11: =IF($A11="","",IFERROR(INDEX('INVENTORY MASTER'!$G$4:$G$63,MATCH($A11,'INVENTORY MASTER'!$A$4:$A$63,0)),"")) | C11: =IF($A11="","",IFERROR(INDEX('INVENTORY MASTER'!$H$4:$H$63,MATCH($A11,'INVENTORY MASTER'!$A$4:$A$63,0)),"")) | D11: =IF($A11="","",IFERROR(INDEX('INVENTORY MASTER'!$I$4:$I$63,MATCH($A11,'INVENTORY MASTER'!$A$4:$A$63,0)),"")) | E11: =IF($A11="","",IFERROR(INDEX('INVENTORY MASTER'!$J$4:$J$63,MATCH($A11,'INVENTORY MASTER'!$A$4:$A$63,0)),"")) | F11: =IF($A11="","",IFERROR(INDEX('INVENTORY MASTER'!$V$4:$V$63,MATCH($A11,'INVENTORY MASTER'!$A$4:$A$63,0)),"")) | G11: =IF($A11="","",IFERROR(INDEX('INVENTORY MASTER'!$T$4:$T$63,MATCH($A11,'INVENTORY MASTER'!$A$4:$A$63,0)),"")) | K11: =IF($A11="","",IFERROR(INDEX('INVENTORY MASTER'!$U$4:$U$63,MATCH($A11,'INVENTORY MASTER'!$A$4:$A$63,0)),"")) | L11: =IF($A11="","",IFERROR(INDEX('INVENTORY MASTER'!$U$4:$U$63,MATCH($A11,'INVENTORY MASTER'!$A$4:$A$63,0)),"")) | M11: =IF($A11="","",IFERROR(INDEX('INVENTORY MASTER'!$W$4:$W$63,MATCH($A11,'INVENTORY MASTER'!$A$4:$A$63,0)),"")) | N11: =IF($A11="","",IFERROR(INDEX('INVENTORY MASTER'!$X$4:$X$63,MATCH($A11,'INVENTORY MASTER'!$A$4:$A$63,0)),"")) | O11: =IF($A11="","",IFERROR(INDEX('INVENTORY MASTER'!$Y$4:$Y$63,MATCH($A11,'INVENTORY MASTER'!$A$4:$A$63,0)),"")) | S11: =IF($A11="","",IFERROR(INDEX('INVENTORY MASTER'!$Z$4:$Z$63,MATCH($A11,'INVENTORY MASTER'!$A$4:$A$63,0)),"")) | T11: =IF($A11="","",IFERROR(INDEX('INVENTORY MASTER'!$AI$4:$AI$63,MATCH($A11,'INVENTORY MASTER'!$A$4:$A$63,0)),"")) | U11: =IF($A11="","",IFERROR(INDEX('INVENTORY MASTER'!$AM$4:$AM$63,MATCH($A11,'INVENTORY MASTER'!$A$4:$A$63,0)),"")) | V11: =IF($A11="","",IFERROR(INDEX('INVENTORY MASTER'!$AO$4:$AO$63,MATCH($A11,'INVENTORY MASTER'!$A$4:$A$63,0)),"")) | W11: =IF($A11="","",IFERROR(INDEX('INVENTORY MASTER'!$AS$4:$AS$63,MATCH($A11,'INVENTORY MASTER'!$A$4:$A$63,0)),"")) | X11: =IF($A11="","",IFERROR(INDEX('INVENTORY MASTER'!$AR$4:$AR$63,MATCH($A11,'INVENTORY MASTER'!$A$4:$A$63,0)),""))
B12: =IF($A12="","",IFERROR(INDEX('INVENTORY MASTER'!$G$4:$G$63,MATCH($A12,'INVENTORY MASTER'!$A$4:$A$63,0)),"")) | C12: =IF($A12="","",IFERROR(INDEX('INVENTORY MASTER'!$H$4:$H$63,MATCH($A12,'INVENTORY MASTER'!$A$4:$A$63,0)),"")) | D12: =IF($A12="","",IFERROR(INDEX('INVENTORY MASTER'!$I$4:$I$63,MATCH($A12,'INVENTORY MASTER'!$A$4:$A$63,0)),"")) | E12: =IF($A12="","",IFERROR(INDEX('INVENTORY MASTER'!$J$4:$J$63,MATCH($A12,'INVENTORY MASTER'!$A$4:$A$63,0)),"")) | F12: =IF($A12="","",IFERROR(INDEX('INVENTORY MASTER'!$V$4:$V$63,MATCH($A12,'INVENTORY MASTER'!$A$4:$A$63,0)),"")) | G12: =IF($A12="","",IFERROR(INDEX('INVENTORY MASTER'!$T$4:$T$63,MATCH($A12,'INVENTORY MASTER'!$A$4:$A$63,0)),"")) | K12: =IF($A12="","",IFERROR(INDEX('INVENTORY MASTER'!$U$4:$U$63,MATCH($A12,'INVENTORY MASTER'!$A$4:$A$63,0)),"")) | L12: =IF($A12="","",IFERROR(INDEX('INVENTORY MASTER'!$U$4:$U$63,MATCH($A12,'INVENTORY MASTER'!$A$4:$A$63,0)),"")) | M12: =IF($A12="","",IFERROR(INDEX('INVENTORY MASTER'!$W$4:$W$63,MATCH($A12,'INVENTORY MASTER'!$A$4:$A$63,0)),"")) | N12: =IF($A12="","",IFERROR(INDEX('INVENTORY MASTER'!$X$4:$X$63,MATCH($A12,'INVENTORY MASTER'!$A$4:$A$63,0)),"")) | O12: =IF($A12="","",IFERROR(INDEX('INVENTORY MASTER'!$Y$4:$Y$63,MATCH($A12,'INVENTORY MASTER'!$A$4:$A$63,0)),"")) | S12: =IF($A12="","",IFERROR(INDEX('INVENTORY MASTER'!$Z$4:$Z$63,MATCH($A12,'INVENTORY MASTER'!$A$4:$A$63,0)),"")) | T12: =IF($A12="","",IFERROR(INDEX('INVENTORY MASTER'!$AI$4:$AI$63,MATCH($A12,'INVENTORY MASTER'!$A$4:$A$63,0)),"")) | U12: =IF($A12="","",IFERROR(INDEX('INVENTORY MASTER'!$AM$4:$AM$63,MATCH($A12,'INVENTORY MASTER'!$A$4:$A$63,0)),"")) | V12: =IF($A12="","",IFERROR(INDEX('INVENTORY MASTER'!$AO$4:$AO$63,MATCH($A12,'INVENTORY MASTER'!$A$4:$A$63,0)),"")) | W12: =IF($A12="","",IFERROR(INDEX('INVENTORY MASTER'!$AS$4:$AS$63,MATCH($A12,'INVENTORY MASTER'!$A$4:$A$63,0)),"")) | X12: =IF($A12="","",IFERROR(INDEX('INVENTORY MASTER'!$AR$4:$AR$63,MATCH($A12,'INVENTORY MASTER'!$A$4:$A$63,0)),""))
B13: =IF($A13="","",IFERROR(INDEX('INVENTORY MASTER'!$G$4:$G$63,MATCH($A13,'INVENTORY MASTER'!$A$4:$A$63,0)),"")) | C13: =IF($A13="","",IFERROR(INDEX('INVENTORY MASTER'!$H$4:$H$63,MATCH($A13,'INVENTORY MASTER'!$A$4:$A$63,0)),"")) | D13: =IF($A13="","",IFERROR(INDEX('INVENTORY MASTER'!$I$4:$I$63,MATCH($A13,'INVENTORY MASTER'!$A$4:$A$63,0)),"")) | E13: =IF($A13="","",IFERROR(INDEX('INVENTORY MASTER'!$J$4:$J$63,MATCH($A13,'INVENTORY MASTER'!$A$4:$A$63,0)),"")) | F13: =IF($A13="","",IFERROR(INDEX('INVENTORY MASTER'!$V$4:$V$63,MATCH($A13,'INVENTORY MASTER'!$A$4:$A$63,0)),"")) | G13: =IF($A13="","",IFERROR(INDEX('INVENTORY MASTER'!$T$4:$T$63,MATCH($A13,'INVENTORY MASTER'!$A$4:$A$63,0)),"")) | K13: =IF($A13="","",IFERROR(INDEX('INVENTORY MASTER'!$U$4:$U$63,MATCH($A13,'INVENTORY MASTER'!$A$4:$A$63,0)),"")) | L13: =IF($A13="","",IFERROR(INDEX('INVENTORY MASTER'!$U$4:$U$63,MATCH($A13,'INVENTORY MASTER'!$A$4:$A$63,0)),"")) | M13: =IF($A13="","",IFERROR(INDEX('INVENTORY MASTER'!$W$4:$W$63,MATCH($A13,'INVENTORY MASTER'!$A$4:$A$63,0)),"")) | N13: =IF($A13="","",IFERROR(INDEX('INVENTORY MASTER'!$X$4:$X$63,MATCH($A13,'INVENTORY MASTER'!$A$4:$A$63,0)),"")) | O13: =IF($A13="","",IFERROR(INDEX('INVENTORY MASTER'!$Y$4:$Y$63,MATCH($A13,'INVENTORY MASTER'!$A$4:$A$63,0)),"")) | S13: =IF($A13="","",IFERROR(INDEX('INVENTORY MASTER'!$Z$4:$Z$63,MATCH($A13,'INVENTORY MASTER'!$A$4:$A$63,0)),"")) | T13: =IF($A13="","",IFERROR(INDEX('INVENTORY MASTER'!$AI$4:$AI$63,MATCH($A13,'INVENTORY MASTER'!$A$4:$A$63,0)),"")) | U13: =IF($A13="","",IFERROR(INDEX('INVENTORY MASTER'!$AM$4:$AM$63,MATCH($A13,'INVENTORY MASTER'!$A$4:$A$63,0)),"")) | V13: =IF($A13="","",IFERROR(INDEX('INVENTORY MASTER'!$AO$4:$AO$63,MATCH($A13,'INVENTORY MASTER'!$A$4:$A$63,0)),"")) | W13: =IF($A13="","",IFERROR(INDEX('INVENTORY MASTER'!$AS$4:$AS$63,MATCH($A13,'INVENTORY MASTER'!$A$4:$A$63,0)),"")) | X13: =IF($A13="","",IFERROR(INDEX('INVENTORY MASTER'!$AR$4:$AR$63,MATCH($A13,'INVENTORY MASTER'!$A$4:$A$63,0)),""))
B14: =IF($A14="","",IFERROR(INDEX('INVENTORY MASTER'!$G$4:$G$63,MATCH($A14,'INVENTORY MASTER'!$A$4:$A$63,0)),"")) | C14: =IF($A14="","",IFERROR(INDEX('INVENTORY MASTER'!$H$4:$H$63,MATCH($A14,'INVENTORY MASTER'!$A$4:$A$63,0)),"")) | D14: =IF($A14="","",IFERROR(INDEX('INVENTORY MASTER'!$I$4:$I$63,MATCH($A14,'INVENTORY MASTER'!$A$4:$A$63,0)),"")) | E14: =IF($A14="","",IFERROR(INDEX('INVENTORY MASTER'!$J$4:$J$63,MATCH($A14,'INVENTORY MASTER'!$A$4:$A$63,0)),"")) | F14: =IF($A14="","",IFERROR(INDEX('INVENTORY MASTER'!$V$4:$V$63,MATCH($A14,'INVENTORY MASTER'!$A$4:$A$63,0)),"")) | G14: =IF($A14="","",IFERROR(INDEX('INVENTORY MASTER'!$T$4:$T$63,MATCH($A14,'INVENTORY MASTER'!$A$4:$A$63,0)),"")) | K14: =IF($A14="","",IFERROR(INDEX('INVENTORY MASTER'!$U$4:$U$63,MATCH($A14,'INVENTORY MASTER'!$A$4:$A$63,0)),"")) | L14: =IF($A14="","",IFERROR(INDEX('INVENTORY MASTER'!$U$4:$U$63,MATCH($A14,'INVENTORY MASTER'!$A$4:$A$63,0)),"")) | M14: =IF($A14="","",IFERROR(INDEX('INVENTORY MASTER'!$W$4:$W$63,MATCH($A14,'INVENTORY MASTER'!$A$4:$A$63,0)),"")) | N14: =IF($A14="","",IFERROR(INDEX('INVENTORY MASTER'!$X$4:$X$63,MATCH($A14,'INVENTORY MASTER'!$A$4:$A$63,0)),"")) | O14: =IF($A14="","",IFERROR(INDEX('INVENTORY MASTER'!$Y$4:$Y$63,MATCH($A14,'INVENTORY MASTER'!$A$4:$A$63,0)),"")) | S14: =IF($A14="","",IFERROR(INDEX('INVENTORY MASTER'!$Z$4:$Z$63,MATCH($A14,'INVENTORY MASTER'!$A$4:$A$63,0)),"")) | T14: =IF($A14="","",IFERROR(INDEX('INVENTORY MASTER'!$AI$4:$AI$63,MATCH($A14,'INVENTORY MASTER'!$A$4:$A$63,0)),"")) | U14: =IF($A14="","",IFERROR(INDEX('INVENTORY MASTER'!$AM$4:$AM$63,MATCH($A14,'INVENTORY MASTER'!$A$4:$A$63,0)),"")) | V14: =IF($A14="","",IFERROR(INDEX('INVENTORY MASTER'!$AO$4:$AO$63,MATCH($A14,'INVENTORY MASTER'!$A$4:$A$63,0)),"")) | W14: =IF($A14="","",IFERROR(INDEX('INVENTORY MASTER'!$AS$4:$AS$63,MATCH($A14,'INVENTORY MASTER'!$A$4:$A$63,0)),"")) | X14: =IF($A14="","",IFERROR(INDEX('INVENTORY MASTER'!$AR$4:$AR$63,MATCH($A14,'INVENTORY MASTER'!$A$4:$A$63,0)),""))
B15: =IF($A15="","",IFERROR(INDEX('INVENTORY MASTER'!$G$4:$G$63,MATCH($A15,'INVENTORY MASTER'!$A$4:$A$63,0)),"")) | C15: =IF($A15="","",IFERROR(INDEX('INVENTORY MASTER'!$H$4:$H$63,MATCH($A15,'INVENTORY MASTER'!$A$4:$A$63,0)),"")) | D15: =IF($A15="","",IFERROR(INDEX('INVENTORY MASTER'!$I$4:$I$63,MATCH($A15,'INVENTORY MASTER'!$A$4:$A$63,0)),"")) | E15: =IF($A15="","",IFERROR(INDEX('INVENTORY MASTER'!$J$4:$J$63,MATCH($A15,'INVENTORY MASTER'!$A$4:$A$63,0)),"")) | F15: =IF($A15="","",IFERROR(INDEX('INVENTORY MASTER'!$V$4:$V$63,MATCH($A15,'INVENTORY MASTER'!$A$4:$A$63,0)),"")) | G15: =IF($A15="","",IFERROR(INDEX('INVENTORY MASTER'!$T$4:$T$63,MATCH($A15,'INVENTORY MASTER'!$A$4:$A$63,0)),"")) | K15: =IF($A15="","",IFERROR(INDEX('INVENTORY MASTER'!$U$4:$U$63,MATCH($A15,'INVENTORY MASTER'!$A$4:$A$63,0)),"")) | L15: =IF($A15="","",IFERROR(INDEX('INVENTORY MASTER'!$U$4:$U$63,MATCH($A15,'INVENTORY MASTER'!$A$4:$A$63,0)),"")) | M15: =IF($A15="","",IFERROR(INDEX('INVENTORY MASTER'!$W$4:$W$63,MATCH($A15,'INVENTORY MASTER'!$A$4:$A$63,0)),"")) | N15: =IF($A15="","",IFERROR(INDEX('INVENTORY MASTER'!$X$4:$X$63,MATCH($A15,'INVENTORY MASTER'!$A$4:$A$63,0)),"")) | O15: =IF($A15="","",IFERROR(INDEX('INVENTORY MASTER'!$Y$4:$Y$63,MATCH($A15,'INVENTORY MASTER'!$A$4:$A$63,0)),"")) | S15: =IF($A15="","",IFERROR(INDEX('INVENTORY MASTER'!$Z$4:$Z$63,MATCH($A15,'INVENTORY MASTER'!$A$4:$A$63,0)),"")) | T15: =IF($A15="","",IFERROR(INDEX('INVENTORY MASTER'!$AI$4:$AI$63,MATCH($A15,'INVENTORY MASTER'!$A$4:$A$63,0)),"")) | U15: =IF($A15="","",IFERROR(INDEX('INVENTORY MASTER'!$AM$4:$AM$63,MATCH($A15,'INVENTORY MASTER'!$A$4:$A$63,0)),"")) | V15: =IF($A15="","",IFERROR(INDEX('INVENTORY MASTER'!$AO$4:$AO$63,MATCH($A15,'INVENTORY MASTER'!$A$4:$A$63,0)),"")) | W15: =IF($A15="","",IFERROR(INDEX('INVENTORY MASTER'!$AS$4:$AS$63,MATCH($A15,'INVENTORY MASTER'!$A$4:$A$63,0)),"")) | X15: =IF($A15="","",IFERROR(INDEX('INVENTORY MASTER'!$AR$4:$AR$63,MATCH($A15,'INVENTORY MASTER'!$A$4:$A$63,0)),""))
